<?xml version="1.0" encoding="utf-8"?>
<!-- This URDF was automatically created by SolidWorks to URDF Exporter! Originally created by Stephen Brawner (brawner@gmail.com) 
     Commit Version: 1.6.0-4-g7f85cfe  Build Version: 1.6.7995.38578
     For more information, please see http://wiki.ros.org/sw_urdf_exporter -->
<robot
  name="arm">
  <link
    name="base_link">
    <inertial>
      <origin
        xyz="3.0919E-35 -1.3477E-16 0.0386"
        rpy="0 0 0" />
      <mass
        value="0.31416" />
      <inertia
        ixx="0.00049932"
        ixy="1.6802E-36"
        ixz="-3.4231E-36"
        iyy="0.00049932"
        iyz="-1.4132E-19"
        izz="0.00054161" />
    </inertial>
    <visual>
      <origin
        xyz="0 0 0"
        rpy="0 0 0" />
      <geometry>
        <mesh
          filename="package://arm/meshes/base_link.STL" />
      </geometry>
      <material
        name="">
        <color
          rgba="0.45294 0.45294 0.45294 1" />
      </material>
    </visual>
    <collision>
      <origin
        xyz="0 0 0"
        rpy="0 0 0" />
      <geometry>
        <mesh
          filename="package://arm/meshes/base_link.STL" />
      </geometry>
    </collision>
  </link>
  <link
    name="link_1">
    <inertial>
      <origin
        xyz="-8.4523E-07 0.0014603 0.016557"
        rpy="0 0 0" />
      <mass
        value="0.3873" />
      <inertia
        ixx="0.00074262"
        ixy="1.5658E-09"
        ixz="-5.9387E-10"
        iyy="0.00071002"
        iyz="9.3616E-06"
        izz="0.00057485" />
    </inertial>
    <visual>
      <origin
        xyz="0 0 0"
        rpy="0 0 0" />
      <geometry>
        <mesh
          filename="package://arm/meshes/link_1.STL" />
      </geometry>
      <material
        name="">
        <color
          rgba="0.65294 0.65294 0.65294 1" />
      </material>
    </visual>
    <collision>
      <origin
        xyz="0 0 0"
        rpy="0 0 0" />
      <geometry>
        <mesh
          filename="package://arm/meshes/link_1.STL" />
      </geometry>
    </collision>
  </link>
  <joint
    name="joint_1"
    type="revolute">
    <origin
      xyz="0 0 0.12"
      rpy="-1.5708 0 0" />
    <parent
      link="base_link" />
    <child
      link="link_1" />
    <axis
      xyz="0 -1 0" />
    <limit
      lower="-3.142"
      upper="3.142"
      effort="300"
      velocity="3" />
  </joint>
  <link
    name="link_2">
    <inertial>
      <origin
        xyz="-0.00053784 -3.1131E-07 0.14452"
        rpy="0 0 0" />
      <mass
        value="1.0516" />
      <inertia
        ixx="0.0066453"
        ixy="-1.5658E-09"
        ixz="-9.3616E-06"
        iyy="0.0066779"
        iyz="-5.9387E-10"
        izz="0.0010452" />
    </inertial>
    <visual>
      <origin
        xyz="0 0 0"
        rpy="0 0 1.5708" />
      <geometry>
        <mesh
          filename="package://arm/meshes/link_2.STL" />
      </geometry>
      <material
        name="">
        <color
          rgba="0.65294 0.65294 0.65294 1" />
      </material>
    </visual>
    <collision>
      <origin
        xyz="0 0 0"
        rpy="0 0 0" />
      <geometry>
        <mesh
          filename="package://arm/meshes/link_2.STL" />
      </geometry>
    </collision>
  </link>
  <joint
    name="joint_2"
    type="revolute">
    <origin
      xyz="0 0 0.11"
      rpy="1.5708 0 0" />
    <parent
      link="link_1" />
    <child
      link="link_2" />
    <axis
      xyz="0 1 0" />
    <limit
      lower="-3.142"
      upper="3.142"
      effort="200"
      velocity="3" />
  </joint>
  <link
    name="link_3">
    <inertial>
      <origin
        xyz="8.4523E-07 -0.0014603 0.016557"
        rpy="0 0 0" />
      <mass
        value="0.3873" />
      <inertia
        ixx="0.00074262"
        ixy="1.5658E-09"
        ixz="5.9387E-10"
        iyy="0.00071002"
        iyz="-9.3616E-06"
        izz="0.00057485" />
    </inertial>
    <visual>
      <origin
        xyz="0 0 0"
        rpy="0 0 0" />
      <geometry>
        <mesh
          filename="package://arm/meshes/link_3.STL" />
      </geometry>
      <material
        name="">
        <color
          rgba="0.65294 0.65294 0.65294 1" />
      </material>
    </visual>
    <collision>
      <origin
        xyz="0 0 0"
        rpy="0 0 0" />
      <geometry>
        <mesh
          filename="package://arm/meshes/link_3.STL" />
      </geometry>
    </collision>
  </link>
  <joint
    name="joint_3"
    type="revolute">
    <origin
      xyz="0 0 0.42"
      rpy="1.5708 0 0" />
    <parent
      link="link_2" />
    <child
      link="link_3" />
    <axis
      xyz="0 1 0" />
    <limit
      lower="-3.142"
      upper="3.142"
      effort="200"
      velocity="3" />
  </joint>
  <link
    name="link_4">
    <inertial>
      <origin
        xyz="0.00053784 3.1131E-07 0.14452"
        rpy="0 0 0" />
      <mass
        value="1.0516" />
      <inertia
        ixx="0.0066453"
        ixy="-1.5658E-09"
        ixz="9.3616E-06"
        iyy="0.0066779"
        iyz="5.9387E-10"
        izz="0.0010452" />
    </inertial>
    <visual>
      <origin
        xyz="0 0 0"
        rpy="0 0 1.5708" />
      <geometry>
        <mesh
          filename="package://arm/meshes/link_4.STL" />
      </geometry>
      <material
        name="">
        <color
          rgba="0.65294 0.65294 0.65294 1" />
      </material>
    </visual>
    <collision>
      <origin
        xyz="0 0 0"
        rpy="0 0 0" />
      <geometry>
        <mesh
          filename="package://arm/meshes/link_4.STL" />
      </geometry>
    </collision>
  </link>
  <joint
    name="joint_4"
    type="revolute">
    <origin
      xyz="0 0 0.11"
      rpy="-1.5708 0 0" />
    <parent
      link="link_3" />
    <child
      link="link_4" />
    <axis
      xyz="0 -1 0" />
    <limit
      lower="-3.142"
      upper="3.142"
      effort="200"
      velocity="3" />
  </joint>
  <link
    name="link_5">
    <inertial>
      <origin
        xyz="0.016557 0.0014603 8.4523E-07"
        rpy="0 0 0" />
      <mass
        value="0.3873" />
      <inertia
        ixx="0.00057485"
        ixy="9.3616E-06"
        ixz="5.9387E-10"
        iyy="0.00071002"
        iyz="-1.5658E-09"
        izz="0.00074262" />
    </inertial>
    <visual>
      <origin
        xyz="0 0 0"
        rpy="0 -1.5708 0" />
      <geometry>
        <mesh
          filename="package://arm/meshes/link_5.STL" />
      </geometry>
      <material
        name="">
        <color
          rgba="0.65294 0.65294 0.65294 1" />
      </material>
    </visual>
    <collision>
      <origin
        xyz="0 0 0"
        rpy="0 0 0" />
      <geometry>
        <mesh
          filename="package://arm/meshes/link_5.STL" />
      </geometry>
    </collision>
  </link>
  <joint
    name="joint_5"
    type="revolute">
    <origin
      xyz="0 0 0.42"
      rpy="-1.5708 0 0" />
    <parent
      link="link_4" />
    <child
      link="link_5" />
    <axis
      xyz="0 -1 0" />
    <limit
      lower="-3.142"
      upper="3.142"
      effort="200"
      velocity="3" />
  </joint>
  <link
    name="link_6">
    <inertial>
      <origin
        xyz="-0.0014603 -8.4523E-07 0.016557"
        rpy="0 0 0" />
      <mass
        value="0.3873" />
      <inertia
        ixx="0.00071002"
        ixy="-1.5658E-09"
        ixz="-9.3616E-06"
        iyy="0.00074262"
        iyz="-5.9387E-10"
        izz="0.00057485" />
    </inertial>
    <visual>
      <origin
        xyz="0 0 0"
        rpy="0 0 1.5708" />
      <geometry>
        <mesh
          filename="package://arm/meshes/link_6.STL" />
      </geometry>
      <material
        name="">
        <color
          rgba="0.65294 0.65294 0.65294 1" />
      </material>
    </visual>
    <collision>
      <origin
        xyz="0 0 0"
        rpy="0 0 0" />
      <geometry>
        <mesh
          filename="package://arm/meshes/link_6.STL" />
      </geometry>
    </collision>
  </link>
  <joint
    name="join_6"
    type="revolute">
    <origin
      xyz="0 0 0.11"
      rpy="1.5708 0 0" />
    <parent
      link="link_5" />
    <child
      link="link_6" />
    <axis
      xyz="0 1 0" />
    <limit
      lower="-3.142"
      upper="3.142"
      effort="200"
      velocity="3" />
  </joint>
  <link
    name="link_7">
    <inertial>
      <origin
        xyz="6.69636084945449E-17 2.26207941267376E-15 -0.00294544608765834"
        rpy="0 0 0" />
      <mass
        value="1.56685176877775" />
      <inertia
        ixx="0.0610235795801421"
        ixy="1.57400570146885E-16"
        ixz="7.01255318732925E-17"
        iyy="0.020369712328907"
        iyz="-5.63852048683335E-18"
        izz="0.0813643115398278" />
    </inertial>
    <visual>
      <origin
        xyz="0 0 0"
        rpy="0 0 0" />
      <geometry>
        <mesh
          filename="package://arm/meshes/link_7.STL" />
      </geometry>
      <material
        name="">
        <color
          rgba="0.65294 0.65294 0.65294 1" />
      </material>
    </visual>
    <collision>
      <origin
        xyz="0 0 0"
        rpy="0 0 0" />
      <geometry>
        <mesh
          filename="package://arm/meshes/link_7.STL" />
      </geometry>
    </collision>
  </link>
  <joint
    name="joint_7"
    type="revolute">
    <origin
      xyz="0 0 0.085"
      rpy="0 0 0" />
    <parent
      link="link_6" />
    <child
      link="link_7" />
    <axis
      xyz="0 0 1" />
    <limit
      lower="-3.142"
      upper="3.142"
      effort="200"
      velocity="3" />
  </joint>
</robot>